Failure # 1 (occurred at 2024-05-19_23-49-07)
[36mray::ImplicitFunc.train()[39m (pid=123992, ip=127.0.0.1, repr=train_tune_parallel)
  File "python\ray\_raylet.pyx", line 830, in ray._raylet.execute_task
  File "python\ray\_raylet.pyx", line 834, in ray._raylet.execute_task
  File "python\ray\_raylet.pyx", line 780, in ray._raylet.execute_task.function_executor
  File "C:\Users\pietr\anaconda3\envs\snnproject\lib\site-packages\ray\_private\function_manager.py", line 674, in actor_method_executor
    return method(__ray_actor, *args, **kwargs)
  File "C:\Users\pietr\anaconda3\envs\snnproject\lib\site-packages\ray\util\tracing\tracing_helper.py", line 466, in _resume_span
    return method(self, *_args, **_kwargs)
  File "C:\Users\pietr\anaconda3\envs\snnproject\lib\site-packages\ray\tune\trainable\trainable.py", line 367, in train
    raise skipped from exception_cause(skipped)
  File "C:\Users\pietr\anaconda3\envs\snnproject\lib\site-packages\ray\tune\trainable\function_trainable.py", line 335, in entrypoint
    return self._trainable_func(
  File "C:\Users\pietr\anaconda3\envs\snnproject\lib\site-packages\ray\util\tracing\tracing_helper.py", line 466, in _resume_span
    return method(self, *_args, **_kwargs)
  File "C:\Users\pietr\anaconda3\envs\snnproject\lib\site-packages\ray\tune\trainable\function_trainable.py", line 652, in _trainable_func
    output = fn()
  File "c:\Users\pietr\OneDrive\Documenti\PIETRO\ETH\SS24\Semester_project\SNN_project\raytune.py", line 217, in train_tune_parallel
    train_loss, train_acc = trainModel(model, train_loader , optimizer, scheduler, criterion, hyperparams, device)
  File "C:\Users\pietr\OneDrive\Documenti\PIETRO\ETH\SS24\Semester_project\SNN_project\util.py", line 498, in trainModel
    loss = criterion(output, targets, errWeights)
  File "C:\Users\pietr\anaconda3\envs\snnproject\lib\site-packages\torch\nn\modules\module.py", line 1511, in _wrapped_call_impl
    return self._call_impl(*args, **kwargs)
  File "C:\Users\pietr\anaconda3\envs\snnproject\lib\site-packages\torch\nn\modules\module.py", line 1520, in _call_impl
    return forward_call(*args, **kwargs)
  File "C:\Users\pietr\OneDrive\Documenti\PIETRO\ETH\SS24\Semester_project\SNN_project\SequenceLoss.py", line 18, in forward
    logits = logitOutput[:, :, self.hyperparams['outputDelay']:]
TypeError: tuple indices must be integers or slices, not tuple
