Failure # 1 (occurred at 2024-05-21_18-52-49)
[36mray::ImplicitFunc.train()[39m (pid=82120, ip=127.0.0.1, repr=train_tune_parallel)
  File "python\ray\_raylet.pyx", line 830, in ray._raylet.execute_task
  File "python\ray\_raylet.pyx", line 834, in ray._raylet.execute_task
  File "python\ray\_raylet.pyx", line 780, in ray._raylet.execute_task.function_executor
  File "C:\Users\pietr\anaconda3\envs\snnproject\lib\site-packages\ray\_private\function_manager.py", line 674, in actor_method_executor
    return method(__ray_actor, *args, **kwargs)
  File "C:\Users\pietr\anaconda3\envs\snnproject\lib\site-packages\ray\util\tracing\tracing_helper.py", line 466, in _resume_span
    return method(self, *_args, **_kwargs)
  File "C:\Users\pietr\anaconda3\envs\snnproject\lib\site-packages\ray\tune\trainable\trainable.py", line 367, in train
    raise skipped from exception_cause(skipped)
  File "C:\Users\pietr\anaconda3\envs\snnproject\lib\site-packages\ray\tune\trainable\function_trainable.py", line 335, in entrypoint
    return self._trainable_func(
  File "C:\Users\pietr\anaconda3\envs\snnproject\lib\site-packages\ray\util\tracing\tracing_helper.py", line 466, in _resume_span
    return method(self, *_args, **_kwargs)
  File "C:\Users\pietr\anaconda3\envs\snnproject\lib\site-packages\ray\tune\trainable\function_trainable.py", line 652, in _trainable_func
    output = fn()
  File "c:\Users\pietr\OneDrive\Documenti\PIETRO\ETH\SS24\Semester_project\SNN_project\raytune.py", line 218, in train_tune_parallel
    train_loss, train_acc = trainModel(model, train_loader , optimizer, scheduler, criterion, hyperparams, device)
  File "C:\Users\pietr\OneDrive\Documenti\PIETRO\ETH\SS24\Semester_project\SNN_project\util.py", line 506, in trainModel
    acc = computeFrameAccuracy(outputs, targets, errWeights, hyperparams['outputDelay'])
  File "C:\Users\pietr\OneDrive\Documenti\PIETRO\ETH\SS24\Semester_project\SNN_project\util.py", line 333, in computeFrameAccuracy
    bestClass = np.argmax(snnOutput[:, 0:-1, outputDelay:], axis=1)
  File "C:\Users\pietr\anaconda3\envs\snnproject\lib\site-packages\numpy\core\fromnumeric.py", line 1229, in argmax
    return _wrapfunc(a, 'argmax', axis=axis, out=out, **kwds)
  File "C:\Users\pietr\anaconda3\envs\snnproject\lib\site-packages\numpy\core\fromnumeric.py", line 59, in _wrapfunc
    return bound(*args, **kwds)
numpy.core._exceptions._ArrayMemoryError: Unable to allocate 8.70 MiB for an array with shape (64, 1150, 31) and data type float32
